Workbook

Sheet 00_Leia-me
A1: MIP 12 x 12 do Piaui, 2018 - estoques mantidos na base
A3: Aba | B3: Conteudo
A4: 01_Recursos | B4: ENTRADA: bloco I da TRUR - producao, importacoes, margens e impostos
A5: 02_Usos | B5: ENTRADA: bloco II da TRUR - consumo intermediario e demanda final
A6: 03_VA | B6: ENTRADA: valor adicionado da TRUR e pessoal ocupado (fonte externa)
A7: 04_Conferencias | B7: Identidades contabeis da TRUR - ver a nota sobre a folga da fonte
A8: 05_ALFA | B8: Base de distribuicao (usos sem estoques) e matriz ALFA
A9: 06_M_comercio | B9: Margem de comercio embutida e a compensacao na linha do Comercio
A10: 07_M_transporte | B10: Margem de transporte embutida e a compensacao na linha do Transporte
A11: 08_M_impostos | B11: Base sem exportacao internacional e os impostos distribuidos
A12: 09_M_importacoes | B12: Base sem nenhuma exportacao e as importacoes (outras UFs e outros paises)
A13: 10_Usos_basicos | B13: Usos a precos de consumidor e, abaixo, a precos basicos
A14: 11_D | B14: Matriz D de participacao de mercado (atividade x produto)
... A24: 22_Simulacao | B24: Simulador simplificado de choque de demanda (conferencia com o site)
A26: Fonte: IBGE, Tabela de Recursos e Usos Regional (TRUR) 2018, Piaui (UF 22),
A27: nivel 12. Valores correntes em R$ 1 000 000. Metodologia de Guilhoto e
A28: Sesso Filho (2005).
A30: As abas 01 a 03 sao as unicas com numeros digitados; todas as demais sao
A31: formulas que referenciam as abas anteriores. Alterar uma celula de entrada
A32: recalcula a MIP inteira.
A34: ATENCAO - a TRUR publicada e arredondada e nao fecha exatamente: ha folga
A35: de balanceamento de ate ~0,24 (R$ milhao) em Transporte e ~-0,04 em
A36: Eletricidade e gas. Essa folga e da fonte, nao do metodo, e reaparece nos
A37: erros da aba 19_Diagnostico. Ver a aba 04_Conferencias.
A39: O pessoal ocupado da aba 03 NAO vem da TRUR: e dado externo de emprego,
A40: copiado de vale_perobelli/MIP2018PI_12s.xlsx.
... A57: Comparacao das tres: mippi18_excel/mippi18_excel_compara.R

Sheet 01_Recursos
A1: Codigo - Produto | B1: 01 - Agropecuária | C1: 02 - Indústrias extrativas | D1: 03 - Indústrias de transformação | E1: 04 - Eletricidade e gás, água, esgoto e gestão de resíduos | F1: 05 - Construção | G1: 06 - Comércio | H1: 07 - Transporte, armazenagem e correio | I1: 08 - Informação e comunicação | J1: 09 - Atividades financeiras, de seguros e serviços relacionados | K1: 10 - Atividades imobiliárias | L1: 11 - Outras atividades de serviços | M1: 12 - Administração, defesa, saúde e educação públicas e seguridade social | N1: Total das atividades | O1: Importacoes de outros paises | P1: Importacoes de outras UFs | Q1: Importacoes totais | R1: Oferta total a precos basicos | S1: Margem de comercio | T1: Margem de transporte | U1: Impostos liquidos sobre produtos | V1: Oferta total a precos de consumidor | W1: Producao do produto (soma das atividades)
A2: 01 - Agropecuária | B2: 7330.2675 | C2: 0 | D2: 0 | E2: 0 | F2: 0 | G2: 7.4694667 | H2: 1.9708127e-08 | I2: 0 | J2: 0 | K2: 0 | L2: 0 | M2: 9.760373 | N2: 7347.4974 | O2: 150.07679 | P2: 857.35858 | Q2: 1007.4354 | R2: 8354.9327 | S2: 821.81433 | T2: 115 | U2: 133.13959 | V2: 9424.8867 | W2: =SUM(B2:M2) -> 7347.4974
A3: 02 - Indústrias extrativas | B3: 1.6090295 | C3: 204.40492 | D3: 3.2644119 | E3: 0 | F3: 0 | G3: 0.026474143 | H3: 0 | I3: 0 | J3: 0 | K3: 0 | L3: 0 | M3: 0 | N3: 209.30483 | O3: 54.877082 | P3: 28.152058 | Q3: 83.02914 | R3: 292.33397 | S3: 44.972682 | T3: 53 | U3: 10.381149 | V3: 400.6878 | W3: =SUM(B3:M3) -> 209.30483
A4: 03 - Indústrias de transformação | B4: 203.43795 | C4: 5.3762232 | D4: 7957.9087 | E4: 0 | F4: 0.042203579 | G4: 329.33827 | H4: 2.717647e-08 | I4: 0 | J4: 0 | K4: 0 | L4: 4.9563603 | M4: 0 | N4: 8501.0597 | O4: 3703.1394 | P4: 20567.143 | Q4: 24270.282 | R4: 32771.342 | S4: 9823.7223 | T4: 409 | U4: 3787.1142 | V4: 46791.179 | W4: =SUM(B4:M4) -> 8501.0597
A5: 04 - Eletricidade e gás, água, esgoto e gestão de resíduos | B5: 0 | C5: 0 | D5: 0 | E5: 4035.2476 | F5: 0 | G5: 0 | H5: 0 | I5: 0 | J5: 0 | K5: 0 | L5: 0 | M5: 7.5659239 | N5: 4042.8136 | O5: 48.494222 | P5: 0 | Q5: 48.494222 | R5: 4091.3078 | S5: 12.447119 | T5: 0 | U5: 446.25606 | V5: 4550.011 | W5: =SUM(B5:M5) -> 4042.8136
A6: 05 - Construção | B6: 72.435669 | C6: 0 | D6: 0 | E6: 0 | F6: 5699.7469 | G6: 0 | H6: 0 | I6: 0 | J6: 0 | K6: 0 | L6: 0 | M6: 0 | N6: 5772.1826 | O6: 24.528287 | P6: 162.10475 | Q6: 186.63303 | R6: 5958.8156 | S6: 0 | T6: 0 | U6: 156.40671 | V6: 6115.2223 | W6: =SUM(B6:M6) -> 5772.1826
A7: 06 - Comércio | B7: 0 | C7: 0.15464855 | D7: 144.53766 | E7: 0 | F7: 0 | G7: 9502.032 | H7: 8.8637441 | I7: 0 | J7: 0 | K7: 0 | L7: 18.06034 | M7: 4.6352191 | N7: 9678.2836 | O7: 5.9770329 | P7: 1920.1044 | Q7: 1926.0814 | R7: 11604.365 | S7: -10795.132 | T7: 0 | U7: 7.9699169 | V7: 817.20285 | W7: =SUM(B7:M7) -> 9678.2836
A8: 07 - Transporte, armazenagem e correio | B8: 0 | C8: 0 | D8: 0 | E8: 0 | F8: 0 | G8: 10.119357 | H8: 2554.4041 | I8: 0 | J8: 0 | K8: 0 | L8: 0 | M8: 20.128201 | N8: 2584.6516 | O8: 101.34255 | P8: 669.19816 | Q8: 770.54071 | R8: 3355.1923 | S8: 0 | T8: -577 | U8: 155.83236 | V8: 2934.0247 | W8: =SUM(B8:M8) -> 2584.6516
A9: 08 - Informação e comunicação | B9: 0 | C9: 0 | D9: 0 | E9: 0 | F9: 0 | G9: 2.9691885 | H9: 0.723543 | I9: 1487.4989 | J9: 4.5618035 | K9: 0 | L9: 0.74261611 | M9: 2.7694278 | N9: 1499.2655 | O9: 107.67291 | P9: 301.76273 | Q9: 409.43564 | R9: 1908.7011 | S9: 92.175667 | T9: 0 | U9: 233.56792 | V9: 2234.4447 | W9: =SUM(B9:M9) -> 1499.2655
A10: 09 - Atividades financeiras, de seguros e serviços relacionados | B10: 0 | C10: 0 | D10: 0 | E10: 0 | F10: 0 | G10: 0 | H10: 0 | I10: 0 | J10: 2294.6362 | K10: 0 | L10: 0 | M10: 0 | N10: 2294.6362 | O10: 181.23458 | P10: 3363.8076 | Q10: 3545.0421 | R10: 5839.6784 | S10: 0 | T10: 0 | U10: 251.38189 | V10: 6091.0603 | W10: =SUM(B10:M10) -> 2294.6362
A11: 10 - Atividades imobiliárias | B11: 0.74844446 | C11: 0.37618642 | D11: 39.763046 | E11: 56.730129 | F11: 3.8716848 | G11: 35.862464 | H11: 8.2852157 | I11: 0.14100972 | J11: 42.153476 | K11: 4028.7338 | L11: 36.683971 | M11: 7.2273642 | N11: 4260.5768 | O11: 28.815291 | P11: 174.95249 | Q11: 203.76778 | R11: 4464.3446 | S11: 0 | T11: 0 | U11: 2.0969491 | V11: 4466.4416 | W11: =SUM(B11:M11) -> 4260.5768
A12: 11 - Outras atividades de serviços | B12: 0.28381577 | C12: 0 | D12: 0.13173536 | E12: 0.00042530854 | F12: 3.4308162 | G12: 64.207562 | H12: 81.278273 | I12: 0.11119788 | J12: 6.8485015 | K12: 0 | L12: 9488.5009 | M12: 285.73385 | N12: 9930.527 | O12: 868.58961 | P12: 4256.3662 | Q12: 5124.9558 | R12: 15055.483 | S12: 0 | T12: 0 | U12: 499.86888 | V12: 15555.352 | W12: =SUM(B12:M12) -> 9930.527
A13: 12 - Administração, defesa, saúde e educação públicas e seguridade social | B13: 0 | C13: 0 | D13: 0 | E13: 0 | F13: 0 | G13: 0 | H13: 0 | I13: 0 | J13: 0 | K13: 0 | L13: 0 | M13: 19314.545 | N13: 19314.545 | O13: 0 | P13: 422.67171 | Q13: 422.67171 | R13: 19737.217 | S13: 0 | T13: 0 | U13: 0 | V13: 19737.217 | W13: =SUM(B13:M13) -> 19314.545
A15: Total | B15: =SUM(B2:B13) -> 7608.7824 | C15: =SUM(C2:C13) -> 210.31198 | D15: =SUM(D2:D13) -> 8145.6056 | E15: =SUM(E2:E13) -> 4091.9782 | F15: =SUM(F2:F13) -> 5707.0916 | G15: =SUM(G2:G13) -> 9952.0248 | H15: =SUM(H2:H13) -> 2653.5548 | I15: =SUM(I2:I13) -> 1487.7511 | ... V15: =SUM(V2:V13) -> 119117.73

Sheet 02_Usos
A1: Codigo - Produto | B1: 01 - Agropecuária | C1: 02 - Indústrias extrativas | D1: 03 - Indústrias de transformação | E1: 04 - Eletricidade e gás, água, esgoto e gestão de resíduos | F1: 05 - Construção | G1: 06 - Comércio | H1: 07 - Transporte, armazenagem e correio | I1: 08 - Informação e comunicação | J1: 09 - Atividades financeiras, de seguros e serviços relacionados | K1: 10 - Atividades imobiliárias | L1: 11 - Outras atividades de serviços | M1: 12 - Administração, defesa, saúde e educação públicas e seguridade social | N1: Total das atividades | O1: Exportacoes outros paises | P1: Exportacoes outras UFs | Q1: Exportacoes totais | R1: Consumo do governo | S1: Consumo das familias | T1: Consumo das ISFLSF | U1: FBCF | V1: Variacao de estoques | W1: Demanda final | X1: Demanda total | Y1: CI do produto (soma das atividades)
A2: 01 - Agropecuária | B2: 336.52786 | C2: 0.011701408 | D2: 1591.7223 | E2: 0.26582577 | F2: 9.9470537 | G2: 63.939615 | H2: 0 | I2: 0 | J2: 0 | K2: 0 | L2: 67.900903 | M2: 45.176743 | N2: 2115.492 | O2: 2073.7754 | P2: 1269.6183 | Q2: 3343.3937 | R2: 1.2191883 | S2: 2973.5572 | T2: 0 | U2: 167.61783 | V2: 823.60672 | W2: 7309.3946 | X2: 9424.8867 | Y2: =SUM(B2:M2) -> 2115.492
A3: 02 - Indústrias extrativas | B3: 8.2404914 | C3: 4.6488867 | D3: 139.61354 | E3: 3.7427616 | F3: 94.724711 | G3: 0.50844481 | H3: 0.0042845705 | I3: 0 | J3: 0 | K3: 5.5097789 | L3: 0.3817976 | M3: 1.8826824 | N3: 259.25738 | O3: 3.3882649 | P3: 81.848675 | Q3: 85.23694 | R3: 0 | S3: 0 | T3: 0 | U3: 0 | V3: 56.193479 | W3: 141.43042 | X3: 400.6878 | Y3: =SUM(B3:M3) -> 259.25738
A4: 03 - Indústrias de transformação | B4: 2378.5487 | C4: 61.142098 | D4: 3685.8365 | E4: 427.4252 | F4: 2067.7679 | G4: 943.80323 | H4: 788.92036 | I4: 64.884884 | J4: 32.678772 | K4: 54.565436 | L4: 1245.9919 | M4: 994.02563 | N4: 12745.591 | O4: 546.53567 | P4: 5170.1451 | Q4: 5716.6808 | R4: 114.71822 | S4: 23647.917 | T4: 0 | U4: 2369.6669 | V4: 2196.6048 | W4: 34045.588 | X4: 46791.179 | Y4: =SUM(B4:M4) -> 12745.591
A5: 04 - Eletricidade e gás, água, esgoto e gestão de resíduos | B5: 154.80937 | C5: 7.900908 | D5: 136.96591 | E5: 1480.3103 | F5: 11.009585 | G5: 255.58089 | H5: 26.111449 | I5: 21.74082 | J5: 12.939323 | K5: 7.1191336 | L5: 216.79545 | M5: 382.08587 | N5: 2713.369 | O5: 0 | P5: 613.90952 | Q5: 613.90952 | R5: 0 | S5: 1221.0253 | T5: 0 | U5: 0 | V5: 1.671612 | W5: 1836.6065 | X5: 4549.9755 | Y5: =SUM(B5:M5) -> 2713.369
A6: 05 - Construção | B6: 3.8224895 | C6: 0.013787086 | D6: 2.264245 | E6: 79.02222 | F6: 705.14023 | G6: 11.177303 | H6: 8.3512823 | I6: 33.955801 | J6: 4.9087163 | K6: 10.536414 | L6: 24.851141 | M6: 362.99379 | N6: 1247.0374 | O6: 0 | P6: 0 | Q6: 0 | R6: 0 | S6: 0 | T6: 0 | U6: 4868.1849 | V6: 0 | W6: 4868.1849 | X6: 6115.2223 | Y6: =SUM(B6:M6) -> 1247.0374
A7: 06 - Comércio | B7: 4.0645391 | C7: 0.19920343 | D7: 78.202412 | E7: 12.218688 | F7: 5.2675482 | G7: 70.450246 | H7: 46.636504 | I7: 23.572888 | J7: 0.47196288 | K7: 0.125092 | L7: 12.265165 | M7: 53.081127 | N7: 306.55538 | O7: 26.994692 | P7: 0 | Q7: 26.994692 | R7: 0 | S7: 483.65278 | T7: 0 | U7: 0 | V7: 0 | W7: 510.64747 | X7: 817.20285 | Y7: =SUM(B7:M7) -> 306.55538
A8: 07 - Transporte, armazenagem e correio | B8: 112.1417 | C8: 6.233409 | D8: 405.32122 | E8: 22.46871 | F8: 35.013467 | G8: 475.61402 | H8: 304.93613 | I8: 11.000165 | J8: 27.967707 | K8: 1.895719 | L8: 133.12582 | M8: 205.00275 | N8: 1740.7208 | O8: 16 | P8: 0 | Q8: 16 | R8: 0 | S8: 1177.5397 | T8: 0 | U8: 0 | V8: 0 | W8: 1193.5397 | X8: 2934.2605 | Y8: =SUM(B8:M8) -> 1740.7208
A9: 08 - Informação e comunicação | B9: 0.61710297 | C9: 0.22864689 | D9: 48.77609 | E9: 41.137019 | F9: 16.744161 | G9: 154.23642 | H9: 31.785982 | I9: 261.46494 | J9: 105.33487 | K9: 5.9821949 | L9: 204.74525 | M9: 399.41456 | N9: 1270.4672 | O9: 2.6752358 | P9: 26.678261 | Q9: 29.353497 | R9: 0 | S9: 824.8463 | T9: 0 | U9: 110.23355 | V9: -0.45588277 | W9: 963.97747 | X9: 2234.4447 | Y9: =SUM(B9:M9) -> 1270.4672
A10: 09 - Atividades financeiras, de seguros e serviços relacionados | B10: 130.45603 | C10: 7.3087877 | D10: 183.00486 | E10: 130.82105 | F10: 96.771951 | G10: 246.23948 | H10: 71.125789 | I10: 66.780516 | J10: 366.11925 | K10: 153.22607 | L10: 148.85236 | M10: 670.49076 | N10: 2271.1969 | O10: 8.4055004 | P10: 0 | Q10: 8.4055004 | R10: 7.7394705 | S10: 3803.7186 | T10: 0 | U10: 0 | V10: 0 | W10: 3819.8635 | X10: 6091.0604 | Y10: =SUM(B10:M10) -> 2271.1969
A11: 10 - Atividades imobiliárias | B11: 0.23503353 | C11: 0.45746481 | D11: 21.746612 | E11: 23.239619 | F11: 13.560324 | G11: 369.93406 | H11: 45.167673 | I11: 25.297465 | J11: 22.641905 | K11: 12.590016 | L11: 189.57111 | M11: 52.578599 | N11: 777.01988 | O11: 0 | P11: 3.8794981 | Q11: 3.8794981 | R11: 0 | S11: 3685.5422 | T11: 0 | U11: 0 | V11: 0 | W11: 3689.4217 | X11: 4466.4416 | Y11: =SUM(B11:M11) -> 777.01988
A12: 11 - Outras atividades de serviços | B12: 42.118355 | C12: 12.527528 | D12: 458.77529 | E12: 286.22536 | F12: 178.98604 | G12: 998.8851 | H12: 184.47089 | I12: 338.46968 | J12: 261.46515 | K12: 34.804537 | L12: 903.45327 | M12: 1594.054 | N12: 5294.2352 | O12: 39.490348 | P12: 213.00548 | Q12: 252.49583 | R12: 564.58529 | S12: 8822.4347 | T12: 462.8832 | U12: 158.71751 | V12: 0 | W12: 10261.117 | X12: 15555.352 | Y12: =SUM(B12:M12) -> 5294.2352
A13: 12 - Administração, defesa, saúde e educação públicas e seguridade social | B13: 0 | C13: 0 | D13: 0 | E13: 0 | F13: 0 | G13: 0 | H13: 0 | I13: 0 | J13: 0 | K13: 0 | L13: 0 | M13: 0 | N13: 0 | O13: 0 | P13: 0 | Q13: 0 | R13: 19737.217 | S13: 0 | T13: 0 | U13: 0 | V13: 0 | W13: 19737.217 | X13: 19737.217 | Y13: =SUM(B13:M13) -> 0
A15: Total | B15: =SUM(B2:B13) -> 3171.5817 | C15: =SUM(C2:C13) -> 100.67242 | D15: =SUM(D2:D13) -> 6752.229 | E15: =SUM(E2:E13) -> 2506.8768 | F15: =SUM(F2:F13) -> 3234.9329 | G15: =SUM(G2:G13) -> 3590.3688 | H15: =SUM(H2:H13) -> 1507.5103 | I15: =SUM(I2:I13) -> 847.16715 | ... X15: =SUM(X2:X13) -> 119117.93

Sheet 03_VA
A1: Conta | B1: 01 - Agropecuária | C1: 02 - Indústrias extrativas | D1: 03 - Indústrias de transformação | E1: 04 - Eletricidade e gás, água, esgoto e gestão de resíduos | F1: 05 - Construção | G1: 06 - Comércio | H1: 07 - Transporte, armazenagem e correio | I1: 08 - Informação e comunicação | J1: 09 - Atividades financeiras, de seguros e serviços relacionados | K1: 10 - Atividades imobiliárias | L1: 11 - Outras atividades de serviços | M1: 12 - Administração, defesa, saúde e educação públicas e seguridade social | N1: Total | O1: PIB regional (TRUR)
A2: Valor adicionado bruto | B2: 4437.2008 | C2: 109.63955 | D2: 1393.3766 | E2: 1585.1014 | F2: 2472.1587 | G2: 6361.656 | H2: 1146.0445 | I2: 640.58395 | J2: 1513.6724 | K2: 3742.3795 | L2: 6401.0099 | M2: 14891.579 | N2: 44694.402 | O2: 50378.418
A3: Pessoal ocupado (dado externo - MIP2018PI_12s.xlsx, nao vem da TRUR) | B3: 243000 | C3: 1392 | D3: 65289 | E3: 4319 | F3: 94000 | G3: 259000 | H3: 47000 | I3: 35550 | J3: 33763 | K3: 12688 | L3: 192000 | M3: 240000
A5: Valor adicionado bruto (total) | B5: =N2 -> 44694.402
A6: Impostos liquidos sobre produtos | B6: ='01_Recursos'!$U$15 -> 5684.0156
A7: PIB = VA + impostos | B7: =B5+B6 -> 50378.418
A8: PIB regional publicado na TRUR | B8: =O2 -> 50378.418
A9: Diferenca | B9: =B7-B8 -> 0

Sheet 04_Conferencias
A1: ETAPA 6 - identidades da TRUR
A2: Identidade | B2: Erro maximo | C2: Tipo
A3: Producao do produto = soma das atividades que o produzem | B3: {=MAX(ABS('01_Recursos'!$N$2:$N$13-'01_Recursos'!$W$2:$W$13))} -> 9.094947e-12 | C3: formula de matriz
A4: Importacao total = outros paises + outras UFs | B4: {=MAX(ABS('01_Recursos'!$Q$2:$Q$13-('01_Recursos'!$O$2:$O$13+'01_Recursos'!$P$2:$P$13)))} -> 4.0017767e-11 | C4: formula de matriz
A5: Oferta a precos basicos = producao + importacao total | B5: {=MAX(ABS('01_Recursos'!$R$2:$R$13-('01_Recursos'!$N$2:$N$13+'01_Recursos'!$Q$2:$Q$13)))} -> 8.0035534e-11 | C5: formula de matriz
A6: Oferta a precos de consumidor = basico + margens + impostos | B6: {=MAX(ABS('01_Recursos'!$V$2:$V$13-('01_Recursos'!$R$2:$R$13+'01_Recursos'!$S$2:$S$13+'01_Recursos'!$T$2:$T$13+'01_Recursos'!$U$2:$U$13)))} -> 6.9235284e-11 | C6: formula de matriz
A7: Exportacao total = outros paises + outras UFs | B7: {=MAX(ABS('02_Usos'!$Q$2:$Q$13-('02_Usos'!$O$2:$O$13+'02_Usos'!$P$2:$P$13)))} -> 2.7284841e-12 | C7: formula de matriz
A8: CI do produto = soma das atividades que o consomem | B8: {=MAX(ABS('02_Usos'!$N$2:$N$13-'02_Usos'!$Y$2:$Y$13))} -> 4.1836756e-11 | C8: formula de matriz
A9: Demanda final = exportacao total + os 5 demais componentes | B9: {=MAX(ABS('02_Usos'!$W$2:$W$13-('02_Usos'!$Q$2:$Q$13+'02_Usos'!$R$2:$R$13+'02_Usos'!$S$2:$S$13+'02_Usos'!$T$2:$T$13+'02_Usos'!$U$2:$U$13+'02_Usos'!$V$2:$V$13)))} -> 9.094947e-12 | C9: formula de matriz
A10: Demanda total = CI total + demanda final | B10: {=MAX(ABS('02_Usos'!$X$2:$X$13-('02_Usos'!$N$2:$N$13+'02_Usos'!$W$2:$W$13)))} -> 2.0008883e-11 | C10: formula de matriz
A11: Soma da coluna de margem de comercio = 0 | B11: =ABS(SUM('01_Recursos'!$S$2:$S$13)) -> 3.1349146e-11 | C11: formula comum
A12: Soma da coluna de margem de transporte = 0 | B12: =ABS(SUM('01_Recursos'!$T$2:$T$13)) -> 0 | C12: formula comum
A13: Valor adicionado = producao da atividade - CI a precos de consumidor | B13: {=MAX(ABS('03_VA'!$B$2:$M$2-('01_Recursos'!$B$15:$M$15-'02_Usos'!$B$15:$M$15)))} -> 1.2732926e-11 | C13: formula de matriz
A15: Folga da TRUR: demanda total - oferta a precos de consumidor
A16: (diferenca da fonte publicada, nao do metodo)
A17: 01 - Agropecuária | B17: ='02_Usos'!$X$2-'01_Recursos'!$V$2 -> 0
A18: 02 - Indústrias extrativas | B18: ='02_Usos'!$X$3-'01_Recursos'!$V$3 -> 0
A19: 03 - Indústrias de transformação | B19: ='02_Usos'!$X$4-'01_Recursos'!$V$4 -> -1.0186341e-10
A20: 04 - Eletricidade e gás, água, esgoto e gestão de resíduos | B20: ='02_Usos'!$X$5-'01_Recursos'!$V$5 -> -0.035464606
A21: 05 - Construção | B21: ='02_Usos'!$X$6-'01_Recursos'!$V$6 -> 0
A22: 06 - Comércio | B22: ='02_Usos'!$X$7-'01_Recursos'!$V$7 -> -1.9326762e-12
A23: 07 - Transporte, armazenagem e correio | B23: ='02_Usos'!$X$8-'01_Recursos'!$V$8 -> 0.23582886
A24: 08 - Informação e comunicação | B24: ='02_Usos'!$X$9-'01_Recursos'!$V$9 -> 0
A25: 09 - Atividades financeiras, de seguros e serviços relacionados | B25: ='02_Usos'!$X$10-'01_Recursos'!$V$10 -> 0.00017510846
A26: 10 - Atividades imobiliárias | B26: ='02_Usos'!$X$11-'01_Recursos'!$V$11 -> 0
A27: 11 - Outras atividades de serviços | B27: ='02_Usos'!$X$12-'01_Recursos'!$V$12 -> 0
A28: 12 - Administração, defesa, saúde e educação públicas e seguridade social | B28: ='02_Usos'!$X$13-'01_Recursos'!$V$13 -> 8.0035534e-10

Sheet 05_ALFA
A1: ETAPA 8a - base das margens: sem excluir nenhuma coluna
A2: Produto \ Destino | B2: 01 - Agropecuária | C2: 02 - Indústrias extrativas | D2: 03 - Indústrias de transformação | E2: 04 - Eletricidade e gás, água, esgoto e gestão de resíduos | F2: 05 - Construção | G2: 06 - Comércio | H2: 07 - Transporte, armazenagem e correio | I2: 08 - Informação e comunicação | J2: 09 - Atividades financeiras, de seguros e serviços relacionados | K2: 10 - Atividades imobiliárias | L2: 11 - Outras atividades de serviços | M2: 12 - Administração, defesa, saúde e educação públicas e seguridade social | N2: Exportacoes outros paises | O2: Exportacoes outras UFs | P2: Consumo do governo | Q2: Consumo das familias | R2: Consumo das ISFLSF | S2: FBCF | T2: Variacao de estoques | U2: Total do produto
A3: 01 - Agropecuária | B3: ='02_Usos'!$B$2 -> 336.52786 | C3: ='02_Usos'!$C$2 -> 0.011701408 | D3: ='02_Usos'!$D$2 -> 1591.7223 | E3: ='02_Usos'!$E$2 -> 0.26582577 | F3: ='02_Usos'!$F$2 -> 9.9470537 | G3: ='02_Usos'!$G$2 -> 63.939615 | H3: ='02_Usos'!$H$2 -> 0 | I3: ='02_Usos'!$I$2 -> 0 | J3: ='02_Usos'!$J$2 -> 0 | K3: ='02_Usos'!$K$2 -> 0 | L3: ='02_Usos'!$L$2 -> 67.900903 | M3: ='02_Usos'!$M$2 -> 45.176743 | N3: ='02_Usos'!$O$2 -> 2073.7754 | O3: ='02_Usos'!$P$2 -> 1269.6183 | P3: ='02_Usos'!$R$2 -> 1.2191883 | Q3: ='02_Usos'!$S$2 -> 2973.5572 | R3: ='02_Usos'!$T$2 -> 0 | S3: ='02_Usos'!$U$2 -> 167.61783 | T3: ='02_Usos'!$V$2 -> 823.60672 | U3: =SUM(B3:T3) -> 9424.8867
A4: 02 - Indústrias extrativas | B4: ='02_Usos'!$B$3 -> 8.2404914 | C4: ='02_Usos'!$C$3 -> 4.6488867 | D4: ='02_Usos'!$D$3 -> 139.61354 | E4: ='02_Usos'!$E$3 -> 3.7427616 | F4: ='02_Usos'!$F$3 -> 94.724711 | G4: ='02_Usos'!$G$3 -> 0.50844481 | H4: ='02_Usos'!$H$3 -> 0.0042845705 | I4: ='02_Usos'!$I$3 -> 0 | J4: ='02_Usos'!$J$3 -> 0 | K4: ='02_Usos'!$K$3 -> 5.5097789 | L4: ='02_Usos'!$L$3 -> 0.3817976 | M4: ='02_Usos'!$M$3 -> 1.8826824 | N4: ='02_Usos'!$O$3 -> 3.3882649 | O4: ='02_Usos'!$P$3 -> 81.848675 | P4: ='02_Usos'!$R$3 -> 0 | Q4: ='02_Usos'!$S$3 -> 0 | R4: ='02_Usos'!$T$3 -> 0 | S4: ='02_Usos'!$U$3 -> 0 | T4: ='02_Usos'!$V$3 -> 56.193479 | U4: =SUM(B4:T4) -> 400.6878
A5: 03 - Indústrias de transformação | B5: ='02_Usos'!$B$4 -> 2378.5487 | C5: ='02_Usos'!$C$4 -> 61.142098 | D5: ='02_Usos'!$D$4 -> 3685.8365 | E5: ='02_Usos'!$E$4 -> 427.4252 | F5: ='02_Usos'!$F$4 -> 2067.7679 | G5: ='02_Usos'!$G$4 -> 943.80323 | H5: ='02_Usos'!$H$4 -> 788.92036 | I5: ='02_Usos'!$I$4 -> 64.884884 | J5: ='02_Usos'!$J$4 -> 32.678772 | K5: ='02_Usos'!$K$4 -> 54.565436 | L5: ='02_Usos'!$L$4 -> 1245.9919 | M5: ='02_Usos'!$M$4 -> 994.02563 | N5: ='02_Usos'!$O$4 -> 546.53567 | O5: ='02_Usos'!$P$4 -> 5170.1451 | P5: ='02_Usos'!$R$4 -> 114.71822 | Q5: ='02_Usos'!$S$4 -> 23647.917 | R5: ='02_Usos'!$T$4 -> 0 | S5: ='02_Usos'!$U$4 -> 2369.6669 | T5: ='02_Usos'!$V$4 -> 2196.6048 | U5: =SUM(B5:T5) -> 46791.179
A6: 04 - Eletricidade e gás, água, esgoto e gestão de resíduos | B6: ='02_Usos'!$B$5 -> 154.80937 | C6: ='02_Usos'!$C$5 -> 7.900908 | D6: ='02_Usos'!$D$5 -> 136.96591 | E6: ='02_Usos'!$E$5 -> 1480.3103 | F6: ='02_Usos'!$F$5 -> 11.009585 | G6: ='02_Usos'!$G$5 -> 255.58089 | H6: ='02_Usos'!$H$5 -> 26.111449 | I6: ='02_Usos'!$I$5 -> 21.74082 | J6: ='02_Usos'!$J$5 -> 12.939323 | K6: ='02_Usos'!$K$5 -> 7.1191336 | L6: ='02_Usos'!$L$5 -> 216.79545 | M6: ='02_Usos'!$M$5 -> 382.08587 | N6: ='02_Usos'!$O$5 -> 0 | O6: ='02_Usos'!$P$5 -> 613.90952 | P6: ='02_Usos'!$R$5 -> 0 | Q6: ='02_Usos'!$S$5 -> 1221.0253 | R6: ='02_Usos'!$T$5 -> 0 | S6: ='02_Usos'!$U$5 -> 0 | T6: ='02_Usos'!$V$5 -> 1.671612 | U6: =SUM(B6:T6) -> 4549.9755
A7: 05 - Construção | B7: ='02_Usos'!$B$6 -> 3.8224895 | C7: ='02_Usos'!$C$6 -> 0.013787086 | D7: ='02_Usos'!$D$6 -> 2.264245 | E7: ='02_Usos'!$E$6 -> 79.02222 | F7: ='02_Usos'!$F$6 -> 705.14023 | G7: ='02_Usos'!$G$6 -> 11.177303 | H7: ='02_Usos'!$H$6 -> 8.3512823 | I7: ='02_Usos'!$I$6 -> 33.955801 | J7: ='02_Usos'!$J$6 -> 4.9087163 | K7: ='02_Usos'!$K$6 -> 10.536414 | L7: ='02_Usos'!$L$6 -> 24.851141 | M7: ='02_Usos'!$M$6 -> 362.99379 | N7: ='02_Usos'!$O$6 -> 0 | O7: ='02_Usos'!$P$6 -> 0 | P7: ='02_Usos'!$R$6 -> 0 | Q7: ='02_Usos'!$S$6 -> 0 | R7: ='02_Usos'!$T$6 -> 0 | S7: ='02_Usos'!$U$6 -> 4868.1849 | T7: ='02_Usos'!$V$6 -> 0 | U7: =SUM(B7:T7) -> 6115.2223
A8: 06 - Comércio | B8: ='02_Usos'!$B$7 -> 4.0645391 | C8: ='02_Usos'!$C$7 -> 0.19920343 | D8: ='02_Usos'!$D$7 -> 78.202412 | E8: ='02_Usos'!$E$7 -> 12.218688 | F8: ='02_Usos'!$F$7 -> 5.2675482 | G8: ='02_Usos'!$G$7 -> 70.450246 | H8: ='02_Usos'!$H$7 -> 46.636504 | I8: ='02_Usos'!$I$7 -> 23.572888 | J8: ='02_Usos'!$J$7 -> 0.47196288 | K8: ='02_Usos'!$K$7 -> 0.125092 | L8: ='02_Usos'!$L$7 -> 12.265165 | M8: ='02_Usos'!$M$7 -> 53.081127 | N8: ='02_Usos'!$O$7 -> 26.994692 | O8: ='02_Usos'!$P$7 -> 0 | P8: ='02_Usos'!$R$7 -> 0 | Q8: ='02_Usos'!$S$7 -> 483.65278 | R8: ='02_Usos'!$T$7 -> 0 | S8: ='02_Usos'!$U$7 -> 0 | T8: ='02_Usos'!$V$7 -> 0 | U8: =SUM(B8:T8) -> 817.20285
A9: 07 - Transporte, armazenagem e correio | B9: ='02_Usos'!$B$8 -> 112.1417 | C9: ='02_Usos'!$C$8 -> 6.233409 | D9: ='02_Usos'!$D$8 -> 405.32122 | E9: ='02_Usos'!$E$8 -> 22.46871 | F9: ='02_Usos'!$F$8 -> 35.013467 | G9: ='02_Usos'!$G$8 -> 475.61402 | H9: ='02_Usos'!$H$8 -> 304.93613 | I9: ='02_Usos'!$I$8 -> 11.000165 | J9: ='02_Usos'!$J$8 -> 27.967707 | K9: ='02_Usos'!$K$8 -> 1.895719 | L9: ='02_Usos'!$L$8 -> 133.12582 | M9: ='02_Usos'!$M$8 -> 205.00275 | N9: ='02_Usos'!$O$8 -> 16 | O9: ='02_Usos'!$P$8 -> 0 | P9: ='02_Usos'!$R$8 -> 0 | Q9: ='02_Usos'!$S$8 -> 1177.5397 | R9: ='02_Usos'!$T$8 -> 0 | S9: ='02_Usos'!$U$8 -> 0 | T9: ='02_Usos'!$V$8 -> 0 | U9: =SUM(B9:T9) -> 2934.2605
A10: 08 - Informação e comunicação | B10: ='02_Usos'!$B$9 -> 0.61710297 | C10: ='02_Usos'!$C$9 -> 0.22864689 | D10: ='02_Usos'!$D$9 -> 48.77609 | E10: ='02_Usos'!$E$9 -> 41.137019 | F10: ='02_Usos'!$F$9 -> 16.744161 | G10: ='02_Usos'!$G$9 -> 154.23642 | H10: ='02_Usos'!$H$9 -> 31.785982 | I10: ='02_Usos'!$I$9 -> 261.46494 | J10: ='02_Usos'!$J$9 -> 105.33487 | K10: ='02_Usos'!$K$9 -> 5.9821949 | L10: ='02_Usos'!$L$9 -> 204.74525 | M10: ='02_Usos'!$M$9 -> 399.41456 | N10: ='02_Usos'!$O$9 -> 2.6752358 | O10: ='02_Usos'!$P$9 -> 26.678261 | P10: ='02_Usos'!$R$9 -> 0 | Q10: ='02_Usos'!$S$9 -> 824.8463 | R10: ='02_Usos'!$T$9 -> 0 | S10: ='02_Usos'!$U$9 -> 110.23355 | T10: ='02_Usos'!$V$9 -> -0.45588277 | U10: =SUM(B10:T10) -> 2234.4447
A11: 09 - Atividades financeiras, de seguros e serviços relacionados | B11: ='02_Usos'!$B$10 -> 130.45603 | C11: ='02_Usos'!$C$10 -> 7.3087877 | D11: ='02_Usos'!$D$10 -> 183.00486 | E11: ='02_Usos'!$E$10 -> 130.82105 | F11: ='02_Usos'!$F$10 -> 96.771951 | G11: ='02_Usos'!$G$10 -> 246.23948 | H11: ='02_Usos'!$H$10 -> 71.125789 | I11: ='02_Usos'!$I$10 -> 66.780516 | J11: ='02_Usos'!$J$10 -> 366.11925 | K11: ='02_Usos'!$K$10 -> 153.22607 | L11: ='02_Usos'!$L$10 -> 148.85236 | M11: ='02_Usos'!$M$10 -> 670.49076 | N11: ='02_Usos'!$O$10 -> 8.4055004 | O11: ='02_Usos'!$P$10 -> 0 | P11: ='02_Usos'!$R$10 -> 7.7394705 | Q11: ='02_Usos'!$S$10 -> 3803.7186 | R11: ='02_Usos'!$T$10 -> 0 | S11: ='02_Usos'!$U$10 -> 0 | T11: ='02_Usos'!$V$10 -> 0 | U11: =SUM(B11:T11) -> 6091.0604
A12: 10 - Atividades imobiliárias | B12: ='02_Usos'!$B$11 -> 0.23503353 | C12: ='02_Usos'!$C$11 -> 0.45746481 | D12: ='02_Usos'!$D$11 -> 21.746612 | E12: ='02_Usos'!$E$11 -> 23.239619 | F12: ='02_Usos'!$F$11 -> 13.560324 | G12: ='02_Usos'!$G$11 -> 369.93406 | H12: ='02_Usos'!$H$11 -> 45.167673 | I12: ='02_Usos'!$I$11 -> 25.297465 | J12: ='02_Usos'!$J$11 -> 22.641905 | K12: ='02_Usos'!$K$11 -> 12.590016 | L12: ='02_Usos'!$L$11 -> 189.57111 | M12: ='02_Usos'!$M$11 -> 52.578599 | N12: ='02_Usos'!$O$11 -> 0 | O12: ='02_Usos'!$P$11 -> 3.8794981 | P12: ='02_Usos'!$R$11 -> 0 | Q12: ='02_Usos'!$S$11 -> 3685.5422 | R12: ='02_Usos'!$T$11 -> 0 | S12: ='02_Usos'!$U$11 -> 0 | T12: ='02_Usos'!$V$11 -> 0 | U12: =SUM(B12:T12) -> 4466.4416
A13: 11 - Outras atividades de serviços | B13: ='02_Usos'!$B$12 -> 42.118355 | C13: ='02_Usos'!$C$12 -> 12.527528 | D13: ='02_Usos'!$D$12 -> 458.77529 | E13: ='02_Usos'!$E$12 -> 286.22536 | F13: ='02_Usos'!$F$12 -> 178.98604 | G13: ='02_Usos'!$G$12 -> 998.8851 | H13: ='02_Usos'!$H$12 -> 184.47089 | I13: ='02_Usos'!$I$12 -> 338.46968 | J13: ='02_Usos'!$J$12 -> 261.46515 | K13: ='02_Usos'!$K$12 -> 34.804537 | L13: ='02_Usos'!$L$12 -> 903.45327 | M13: ='02_Usos'!$M$12 -> 1594.054 | N13: ='02_Usos'!$O$12 -> 39.490348 | O13: ='02_Usos'!$P$12 -> 213.00548 | P13: ='02_Usos'!$R$12 -> 564.58529 | Q13: ='02_Usos'!$S$12 -> 8822.4347 | R13: ='02_Usos'!$T$12 -> 462.8832 | S13: ='02_Usos'!$U$12 -> 158.71751 | T13: ='02_Usos'!$V$12 -> 0 | U13: =SUM(B13:T13) -> 15555.352
A14: 12 - Administração, defesa, saúde e educação públicas e seguridade social | B14: ='02_Usos'!$B$13 -> 0 | C14: ='02_Usos'!$C$13 -> 0 | D14: ='02_Usos'!$D$13 -> 0 | E14: ='02_Usos'!$E$13 -> 0 | F14: ='02_Usos'!$F$13 -> 0 | G14: ='02_Usos'!$G$13 -> 0 | H14: ='02_Usos'!$H$13 -> 0 | I14: ='02_Usos'!$I$13 -> 0 | J14: ='02_Usos'!$J$13 -> 0 | K14: ='02_Usos'!$K$13 -> 0 | L14: ='02_Usos'!$L$13 -> 0 | M14: ='02_Usos'!$M$13 -> 0 | N14: ='02_Usos'!$O$13 -> 0 | O14: ='02_Usos'!$P$13 -> 0 | P14: ='02_Usos'!$R$13 -> 19737.217 | Q14: ='02_Usos'!$S$13 -> 0 | R14: ='02_Usos'!$T$13 -> 0 | S14: ='02_Usos'!$U$13 -> 0 | T14: ='02_Usos'!$V$13 -> 0 | U14: =SUM(B14:T14) -> 19737.217
A16: ETAPA 8b - ALFA: cada celula dividida pelo total do produto
A17: Produto \ Destino | B17: 01 - Agropecuária | C17: 02 - Indústrias extrativas | D17: 03 - Indústrias de transformação | E17: 04 - Eletricidade e gás, água, esgoto e gestão de resíduos | F17: 05 - Construção | G17: 06 - Comércio | H17: 07 - Transporte, armazenagem e correio | I17: 08 - Informação e comunicação | J17: 09 - Atividades financeiras, de seguros e serviços relacionados | K17: 10 - Atividades imobiliárias | L17: 11 - Outras atividades de serviços | M17: 12 - Administração, defesa, saúde e educação públicas e seguridade social | N17: Exportacoes outros paises | O17: Exportacoes outras UFs | P17: Consumo do governo | Q17: Consumo das familias | R17: Consumo das ISFLSF | S17: FBCF | T17: Variacao de estoques | U17: Soma da linha (deve ser 1)
A18: 01 - Agropecuária | B18: =IF($U$3=0,0,B$3/$U$3) -> 0.035706303 | C18: =IF($U$3=0,0,C$3/$U$3) -> 1.2415437e-06 | D18: =IF($U$3=0,0,D$3/$U$3) -> 0.16888504 | E18: =IF($U$3=0,0,E$3/$U$3) -> 2.8204665e-05 | F18: =IF($U$3=0,0,F$3/$U$3) -> 0.001055403 | G18: =IF($U$3=0,0,G$3/$U$3) -> 0.0067841256 | H18: =IF($U$3=0,0,H$3/$U$3) -> 0 | I18: =IF($U$3=0,0,I$3/$U$3) -> 0 | ... T18: =IF($U$3=0,0,T$3/$U$3) -> 0.087386379 | U18: =SUM(B18:T18) -> 1
A19: 02 - Indústrias extrativas | B19: =IF($U$4=0,0,B$4/$U$4) -> 0.020565865 | C19: =IF($U$4=0,0,C$4/$U$4) -> 0.011602267 | D19: =IF($U$4=0,0,D$4/$U$4) -> 0.34843473 | E19: =IF($U$4=0,0,E$4/$U$4) -> 0.0093408424 | F19: =IF($U$4=0,0,F$4/$U$4) -> 0.23640528 | G19: =IF($U$4=0,0,G$4/$U$4) -> 0.0012689301 | H19: =IF($U$4=0,0,H$4/$U$4) -> 1.069304e-05 | I19: =IF($U$4=0,0,I$4/$U$4) -> 0 | ... T19: =IF($U$4=0,0,T$4/$U$4) -> 0.14024255 | U19: =SUM(B19:T19) -> 1
A20: 03 - Indústrias de transformação | B20: =IF($U$5=0,0,B$5/$U$5) -> 0.050833272 | C20: =IF($U$5=0,0,C$5/$U$5) -> 0.0013067014 | D20: =IF($U$5=0,0,D$5/$U$5) -> 0.078772037 | E20: =IF($U$5=0,0,E$5/$U$5) -> 0.0091347389 | F20: =IF($U$5=0,0,F$5/$U$5) -> 0.044191404 | G20: =IF($U$5=0,0,G$5/$U$5) -> 0.020170538 | H20: =IF($U$5=0,0,H$5/$U$5) -> 0.016860451 | I20: =IF($U$5=0,0,I$5/$U$5) -> 0.0013866905 | ... T20: =IF($U$5=0,0,T$5/$U$5) -> 0.046944849 | U20: =SUM(B20:T20) -> 1
A21: 04 - Eletricidade e gás, água, esgoto e gestão de resíduos | B21: =IF($U$6=0,0,B$6/$U$6) -> 0.03402422 | C21: =IF($U$6=0,0,C$6/$U$6) -> 0.0017364727 | D21: =IF($U$6=0,0,D$6/$U$6) -> 0.030102561 | E21: =IF($U$6=0,0,E$6/$U$6) -> 0.32534468 | F21: =IF($U$6=0,0,F$6/$U$6) -> 0.0024197021 | G21: =IF($U$6=0,0,G$6/$U$6) -> 0.056171928 | H21: =IF($U$6=0,0,H$6/$U$6) -> 0.0057388108 | I21: =IF($U$6=0,0,I$6/$U$6) -> 0.0047782279 | ... T21: =IF($U$6=0,0,T$6/$U$6) -> 0.00036738923 | U21: =SUM(B21:T21) -> 1
A22: 05 - Construção | B22: =IF($U$7=0,0,B$7/$U$7) -> 0.00062507776 | C22: =IF($U$7=0,0,C$7/$U$7) -> 2.2545518e-06 | D22: =IF($U$7=0,0,D$7/$U$7) -> 0.00037026373 | E22: =IF($U$7=0,0,E$7/$U$7) -> 0.012922215 | F22: =IF($U$7=0,0,F$7/$U$7) -> 0.11530901 | G22: =IF($U$7=0,0,G$7/$U$7) -> 0.0018277835 | H22: =IF($U$7=0,0,H$7/$U$7) -> 0.0013656547 | I22: =IF($U$7=0,0,I$7/$U$7) -> 0.0055526682 | ... T22: =IF($U$7=0,0,T$7/$U$7) -> 0 | U22: =SUM(B22:T22) -> 1
A23: 06 - Comércio | B23: =IF($U$8=0,0,B$8/$U$8) -> 0.0049737211 | C23: =IF($U$8=0,0,C$8/$U$8) -> 0.00024376253 | D23: =IF($U$8=0,0,D$8/$U$8) -> 0.095695227 | E23: =IF($U$8=0,0,E$8/$U$8) -> 0.014951842 | F23: =IF($U$8=0,0,F$8/$U$8) -> 0.006445827 | G23: =IF($U$8=0,0,G$8/$U$8) -> 0.086209007 | H23: =IF($U$8=0,0,H$8/$U$8) -> 0.057068455 | I23: =IF($U$8=0,0,I$8/$U$8) -> 0.028845822 | ... T23: =IF($U$8=0,0,T$8/$U$8) -> 0 | U23: =SUM(B23:T23) -> 1
A24: 07 - Transporte, armazenagem e correio | B24: =IF($U$9=0,0,B$9/$U$9) -> 0.038218044 | C24: =IF($U$9=0,0,C$9/$U$9) -> 0.0021243543 | D24: =IF($U$9=0,0,D$9/$U$9) -> 0.13813403 | E24: =IF($U$9=0,0,E$9/$U$9) -> 0.0076573671 | F24: =IF($U$9=0,0,F$9/$U$9) -> 0.011932637 | G24: =IF($U$9=0,0,G$9/$U$9) -> 0.16208991 | H24: =IF($U$9=0,0,H$9/$U$9) -> 0.10392265 | I24: =IF($U$9=0,0,I$9/$U$9) -> 0.0037488712 | ... T24: =IF($U$9=0,0,T$9/$U$9) -> 0 | U24: =SUM(B24:T24) -> 1
A25: 08 - Informação e comunicação | B25: =IF($U$10=0,0,B$10/$U$10) -> 0.00027617733 | C25: =IF($U$10=0,0,C$10/$U$10) -> 0.00010232828 | D25: =IF($U$10=0,0,D$10/$U$10) -> 0.021829178 | E25: =IF($U$10=0,0,E$10/$U$10) -> 0.018410399 | F25: =IF($U$10=0,0,F$10/$U$10) -> 0.0074936563 | G25: =IF($U$10=0,0,G$10/$U$10) -> 0.069026736 | H25: =IF($U$10=0,0,H$10/$U$10) -> 0.01422545 | I25: =IF($U$10=0,0,I$10/$U$10) -> 0.11701562 | ... T25: =IF($U$10=0,0,T$10/$U$10) -> -0.00020402509 | U25: =SUM(B25:T25) -> 1
A26: 09 - Atividades financeiras, de seguros e serviços relacionados | B26: =IF($U$11=0,0,B$11/$U$11) -> 0.021417622 | C26: =IF($U$11=0,0,C$11/$U$11) -> 0.0011999204 | D26: =IF($U$11=0,0,D$11/$U$11) -> 0.030044828 | E26: =IF($U$11=0,0,E$11/$U$11) -> 0.021477548 | F26: =IF($U$11=0,0,F$11/$U$11) -> 0.015887537 | G26: =IF($U$11=0,0,G$11/$U$11) -> 0.040426372 | H26: =IF($U$11=0,0,H$11/$U$11) -> 0.011677078 | I26: =IF($U$11=0,0,I$11/$U$11) -> 0.010963693 | ... T26: =IF($U$11=0,0,T$11/$U$11) -> 0 | U26: =SUM(B26:T26) -> 1
A27: 10 - Atividades imobiliárias | B27: =IF($U$12=0,0,B$12/$U$12) -> 5.2622099e-05 | C27: =IF($U$12=0,0,C$12/$U$12) -> 0.00010242266 | D27: =IF($U$12=0,0,D$12/$U$12) -> 0.0048688898 | E27: =IF($U$12=0,0,E$12/$U$12) -> 0.005203162 | F27: =IF($U$12=0,0,F$12/$U$12) -> 0.0030360464 | G27: =IF($U$12=0,0,G$12/$U$12) -> 0.082825231 | H27: =IF($U$12=0,0,H$12/$U$12) -> 0.010112675 | I27: =IF($U$12=0,0,I$12/$U$12) -> 0.005663897 | ... T27: =IF($U$12=0,0,T$12/$U$12) -> 0 | U27: =SUM(B27:T27) -> 1
A28: 11 - Outras atividades de serviços | B28: =IF($U$13=0,0,B$13/$U$13) -> 0.002707644 | C28: =IF($U$13=0,0,C$13/$U$13) -> 0.00080535166 | D28: =IF($U$13=0,0,D$13/$U$13) -> 0.029493084 | E28: =IF($U$13=0,0,E$13/$U$13) -> 0.018400443 | F28: =IF($U$13=0,0,F$13/$U$13) -> 0.011506396 | G28: =IF($U$13=0,0,G$13/$U$13) -> 0.064214884 | H28: =IF($U$13=0,0,H$13/$U$13) -> 0.011858998 | I28: =IF($U$13=0,0,I$13/$U$13) -> 0.02175905 | ... T28: =IF($U$13=0,0,T$13/$U$13) -> 0 | U28: =SUM(B28:T28) -> 1
A29: 12 - Administração, defesa, saúde e educação públicas e seguridade social | B29: =IF($U$14=0,0,B$14/$U$14) -> 0 | C29: =IF($U$14=0,0,C$14/$U$14) -> 0 | D29: =IF($U$14=0,0,D$14/$U$14) -> 0 | E29: =IF($U$14=0,0,E$14/$U$14) -> 0 | F29: =IF($U$14=0,0,F$14/$U$14) -> 0 | G29: =IF($U$14=0,0,G$14/$U$14) -> 0 | H29: =IF($U$14=0,0,H$14/$U$14) -> 0 | I29: =IF($U$14=0,0,I$14/$U$14) -> 0 | ... T29: =IF($U$14=0,0,T$14/$U$14) -> 0 | U29: =SUM(B29:T29) -> 1

Sheet 06_M_comercio
A1: ETAPA 9a - margem de Comercio embutida em cada celula (ALFA x margem do produto)
A2: Produto \ Destino | B2: 01 - Agropecuária | C2: 02 - Indústrias extrativas | D2: 03 - Indústrias de transformação | E2: 04 - Eletricidade e gás, água, esgoto e gestão de resíduos | F2: 05 - Construção | G2: 06 - Comércio | H2: 07 - Transporte, armazenagem e correio | I2: 08 - Informação e comunicação | J2: 09 - Atividades financeiras, de seguros e serviços relacionados | K2: 10 - Atividades imobiliárias | L2: 11 - Outras atividades de serviços | M2: 12 - Administração, defesa, saúde e educação públicas e seguridade social | N2: Exportacoes outros paises | O2: Exportacoes outras UFs | P2: Consumo do governo | Q2: Consumo das familias | R2: Consumo das ISFLSF | S2: FBCF | T2: Variacao de estoques
A3: 01 - Agropecuária | B3: ='05_ALFA'!$B$18*'01_Recursos'!$S$2 -> 29.343952 | C3: ='05_ALFA'!$C$18*'01_Recursos'!$S$2 -> 0.0010203184 | D3: ='05_ALFA'!$D$18*'01_Recursos'!$S$2 -> 138.79214 | E3: ='05_ALFA'!$E$18*'01_Recursos'!$S$2 -> 0.023178998 | F3: ='05_ALFA'!$F$18*'01_Recursos'!$S$2 -> 0.86734532 | G3: ='05_ALFA'!$G$18*'01_Recursos'!$S$2 -> 5.5752916 | H3: ='05_ALFA'!$H$18*'01_Recursos'!$S$2 -> 0 | I3: ='05_ALFA'!$I$18*'01_Recursos'!$S$2 -> 0 | J3: ='05_ALFA'!$J$18*'01_Recursos'!$S$2 -> 0 | K3: ='05_ALFA'!$K$18*'01_Recursos'!$S$2 -> 0 | L3: ='05_ALFA'!$L$18*'01_Recursos'!$S$2 -> 5.9207009 | M3: ='05_ALFA'!$M$18*'01_Recursos'!$S$2 -> 3.9392405 | N3: ='05_ALFA'!$N$18*'01_Recursos'!$S$2 -> 180.82534 | O3: ='05_ALFA'!$O$18*'01_Recursos'!$S$2 -> 110.70589 | P3: ='05_ALFA'!$P$18*'01_Recursos'!$S$2 -> 0.10630859 | Q3: ='05_ALFA'!$Q$18*'01_Recursos'!$S$2 -> 259.2829 | R3: ='05_ALFA'!$R$18*'01_Recursos'!$S$2 -> 0 | S3: ='05_ALFA'!$S$18*'01_Recursos'!$S$2 -> 14.615638 | T3: ='05_ALFA'!$T$18*'01_Recursos'!$S$2 -> 71.815378
A4: 02 - Indústrias extrativas | B4: ='05_ALFA'!$B$19*'01_Recursos'!$S$3 -> 0.92490211 | C4: ='05_ALFA'!$C$19*'01_Recursos'!$S$3 -> 0.52178504 | D4: ='05_ALFA'!$D$19*'01_Recursos'!$S$3 -> 15.670044 | E4: ='05_ALFA'!$E$19*'01_Recursos'!$S$3 -> 0.42008273 | F4: ='05_ALFA'!$F$19*'01_Recursos'!$S$3 -> 10.631779 | G4: ='05_ALFA'!$G$19*'01_Recursos'!$S$3 -> 0.057067189 | H4: ='05_ALFA'!$H$19*'01_Recursos'!$S$3 -> 0.00048089466 | I4: ='05_ALFA'!$I$19*'01_Recursos'!$S$3 -> 0 | J4: ='05_ALFA'!$J$19*'01_Recursos'!$S$3 -> 0 | K4: ='05_ALFA'!$K$19*'01_Recursos'!$S$3 -> 0.61841046 | L4: ='05_ALFA'!$L$19*'01_Recursos'!$S$3 -> 0.042852469 | M4: ='05_ALFA'!$M$19*'01_Recursos'!$S$3 -> 0.21130984 | N4: ='05_ALFA'!$N$19*'01_Recursos'!$S$3 -> 0.38029447 | O4: ='05_ALFA'!$O$19*'01_Recursos'!$S$3 -> 9.1865896 | P4: ='05_ALFA'!$P$19*'01_Recursos'!$S$3 -> 0 | Q4: ='05_ALFA'!$Q$19*'01_Recursos'!$S$3 -> 0 | R4: ='05_ALFA'!$R$19*'01_Recursos'!$S$3 -> 0 | S4: ='05_ALFA'!$S$19*'01_Recursos'!$S$3 -> 0 | T4: ='05_ALFA'!$T$19*'01_Recursos'!$S$3 -> 6.3070835
A5: 03 - Indústrias de transformação | B5: ='05_ALFA'!$B$20*'01_Recursos'!$S$4 -> 499.37195 | C5: ='05_ALFA'!$C$20*'01_Recursos'!$S$4 -> 12.836672 | D5: ='05_ALFA'!$D$20*'01_Recursos'!$S$4 -> 773.83462 | E5: ='05_ALFA'!$E$20*'01_Recursos'!$S$4 -> 89.737138 | F5: ='05_ALFA'!$F$20*'01_Recursos'!$S$4 -> 434.12408 | G5: ='05_ALFA'!$G$20*'01_Recursos'!$S$4 -> 198.14976 | H5: ='05_ALFA'!$H$20*'01_Recursos'!$S$4 -> 165.63239 | I5: ='05_ALFA'!$I$20*'01_Recursos'!$S$4 -> 13.622463 | J5: ='05_ALFA'!$J$20*'01_Recursos'!$S$4 -> 6.8608484 | K5: ='05_ALFA'!$K$20*'01_Recursos'!$S$4 -> 11.455913 | L5: ='05_ALFA'!$L$20*'01_Recursos'!$S$4 -> 261.59373 | M5: ='05_ALFA'!$M$20*'01_Recursos'!$S$4 -> 208.69386 | N5: ='05_ALFA'!$N$20*'01_Recursos'!$S$4 -> 114.74416 | O5: ='05_ALFA'!$O$20*'01_Recursos'!$S$4 -> 1085.4625 | P5: ='05_ALFA'!$P$20*'01_Recursos'!$S$4 -> 24.084879 | Q5: ='05_ALFA'!$Q$20*'01_Recursos'!$S$4 -> 4964.837 | R5: ='05_ALFA'!$R$20*'01_Recursos'!$S$4 -> 0 | S5: ='05_ALFA'!$S$20*'01_Recursos'!$S$4 -> 497.50722 | T5: ='05_ALFA'!$T$20*'01_Recursos'!$S$4 -> 461.17316
A6: 04 - Eletricidade e gás, água, esgoto e gestão de resíduos | B6: ='05_ALFA'!$B$21*'01_Recursos'!$S$5 -> 0.42350351 | C6: ='05_ALFA'!$C$21*'01_Recursos'!$S$5 -> 0.021614082 | D6: ='05_ALFA'!$D$21*'01_Recursos'!$S$5 -> 0.37469015 | E6: ='05_ALFA'!$E$21*'01_Recursos'!$S$5 -> 4.0496039 | F6: ='05_ALFA'!$F$21*'01_Recursos'!$S$5 -> 0.030118319 | G6: ='05_ALFA'!$G$21*'01_Recursos'!$S$5 -> 0.69917866 | H6: ='05_ALFA'!$H$21*'01_Recursos'!$S$5 -> 0.071431661 | I6: ='05_ALFA'!$I$21*'01_Recursos'!$S$5 -> 0.059475171 | J6: ='05_ALFA'!$J$21*'01_Recursos'!$S$5 -> 0.035397398 | K6: ='05_ALFA'!$K$21*'01_Recursos'!$S$5 -> 0.019475424 | L6: ='05_ALFA'!$L$21*'01_Recursos'!$S$5 -> 0.59307546 | M6: ='05_ALFA'!$M$21*'01_Recursos'!$S$5 -> 1.0452514 | N6: ='05_ALFA'!$N$21*'01_Recursos'!$S$5 -> 0 | O6: ='05_ALFA'!$O$21*'01_Recursos'!$S$5 -> 1.6794387 | P6: ='05_ALFA'!$P$21*'01_Recursos'!$S$5 -> 0 | Q6: ='05_ALFA'!$Q$21*'01_Recursos'!$S$5 -> 3.3402922 | R6: ='05_ALFA'!$R$21*'01_Recursos'!$S$5 -> 0 | S6: ='05_ALFA'!$S$21*'01_Recursos'!$S$5 -> 0 | T6: ='05_ALFA'!$T$21*'01_Recursos'!$S$5 -> 0.0045729375
A7: 05 - Construção | B7: ='05_ALFA'!$B$22*'01_Recursos'!$S$6 -> 0 | C7: ='05_ALFA'!$C$22*'01_Recursos'!$S$6 -> 0 | D7: ='05_ALFA'!$D$22*'01_Recursos'!$S$6 -> 0 | E7: ='05_ALFA'!$E$22*'01_Recursos'!$S$6 -> 0 | F7: ='05_ALFA'!$F$22*'01_Recursos'!$S$6 -> 0 | G7: ='05_ALFA'!$G$22*'01_Recursos'!$S$6 -> 0 | H7: ='05_ALFA'!$H$22*'01_Recursos'!$S$6 -> 0 | I7: ='05_ALFA'!$I$22*'01_Recursos'!$S$6 -> 0 | J7: ='05_ALFA'!$J$22*'01_Recursos'!$S$6 -> 0 | K7: ='05_ALFA'!$K$22*'01_Recursos'!$S$6 -> 0 | L7: ='05_ALFA'!$L$22*'01_Recursos'!$S$6 -> 0 | M7: ='05_ALFA'!$M$22*'01_Recursos'!$S$6 -> 0 | N7: ='05_ALFA'!$N$22*'01_Recursos'!$S$6 -> 0 | O7: ='05_ALFA'!$O$22*'01_Recursos'!$S$6 -> 0 | P7: ='05_ALFA'!$P$22*'01_Recursos'!$S$6 -> 0 | Q7: ='05_ALFA'!$Q$22*'01_Recursos'!$S$6 -> 0 | R7: ='05_ALFA'!$R$22*'01_Recursos'!$S$6 -> 0 | S7: ='05_ALFA'!$S$22*'01_Recursos'!$S$6 -> 0 | T7: ='05_ALFA'!$T$22*'01_Recursos'!$S$6 -> 0
A8: 06 - Comércio | B8: ='05_ALFA'!$B$23*'01_Recursos'!$S$7 -> -53.691977 | C8: ='05_ALFA'!$C$23*'01_Recursos'!$S$7 -> -2.6314487 | D8: ='05_ALFA'!$D$23*'01_Recursos'!$S$7 -> -1033.0426 | E8: ='05_ALFA'!$E$23*'01_Recursos'!$S$7 -> -161.40711 | F8: ='05_ALFA'!$F$23*'01_Recursos'!$S$7 -> -69.583554 | G8: ='05_ALFA'!$G$23*'01_Recursos'!$S$7 -> -930.63763 | H8: ='05_ALFA'!$H$23*'01_Recursos'!$S$7 -> -616.06151 | I8: ='05_ALFA'!$I$23*'01_Recursos'!$S$7 -> -311.39445 | J8: ='05_ALFA'!$J$23*'01_Recursos'!$S$7 -> -6.2345617 | K8: ='05_ALFA'!$K$23*'01_Recursos'!$S$7 -> -1.6524473 | L8: ='05_ALFA'!$L$23*'01_Recursos'!$S$7 -> -162.02107 | M8: ='05_ALFA'!$M$23*'01_Recursos'!$S$7 -> -701.19405 | N8: ='05_ALFA'!$N$23*'01_Recursos'!$S$7 -> -356.59599 | O8: ='05_ALFA'!$O$23*'01_Recursos'!$S$7 -> 0 | P8: ='05_ALFA'!$P$23*'01_Recursos'!$S$7 -> 0 | Q8: ='05_ALFA'!$Q$23*'01_Recursos'!$S$7 -> -6388.9837 | R8: ='05_ALFA'!$R$23*'01_Recursos'!$S$7 -> 0 | S8: ='05_ALFA'!$S$23*'01_Recursos'!$S$7 -> 0 | T8: ='05_ALFA'!$T$23*'01_Recursos'!$S$7 -> 0
A9: 07 - Transporte, armazenagem e correio | B9: ='05_ALFA'!$B$24*'01_Recursos'!$S$8 -> 0 | C9: ='05_ALFA'!$C$24*'01_Recursos'!$S$8 -> 0 | D9: ='05_ALFA'!$D$24*'01_Recursos'!$S$8 -> 0 | E9: ='05_ALFA'!$E$24*'01_Recursos'!$S$8 -> 0 | F9: ='05_ALFA'!$F$24*'01_Recursos'!$S$8 -> 0 | G9: ='05_ALFA'!$G$24*'01_Recursos'!$S$8 -> 0 | H9: ='05_ALFA'!$H$24*'01_Recursos'!$S$8 -> 0 | I9: ='05_ALFA'!$I$24*'01_Recursos'!$S$8 -> 0 | J9: ='05_ALFA'!$J$24*'01_Recursos'!$S$8 -> 0 | K9: ='05_ALFA'!$K$24*'01_Recursos'!$S$8 -> 0 | L9: ='05_ALFA'!$L$24*'01_Recursos'!$S$8 -> 0 | M9: ='05_ALFA'!$M$24*'01_Recursos'!$S$8 -> 0 | N9: ='05_ALFA'!$N$24*'01_Recursos'!$S$8 -> 0 | O9: ='05_ALFA'!$O$24*'01_Recursos'!$S$8 -> 0 | P9: ='05_ALFA'!$P$24*'01_Recursos'!$S$8 -> 0 | Q9: ='05_ALFA'!$Q$24*'01_Recursos'!$S$8 -> 0 | R9: ='05_ALFA'!$R$24*'01_Recursos'!$S$8 -> 0 | S9: ='05_ALFA'!$S$24*'01_Recursos'!$S$8 -> 0 | T9: ='05_ALFA'!$T$24*'01_Recursos'!$S$8 -> 0
A10: 08 - Informação e comunicação | B10: ='05_ALFA'!$B$25*'01_Recursos'!$S$9 -> 0.02545683 | C10: ='05_ALFA'!$C$25*'01_Recursos'!$S$9 -> 0.0094321776 | D10: ='05_ALFA'!$D$25*'01_Recursos'!$S$9 -> 2.012119 | E10: ='05_ALFA'!$E$25*'01_Recursos'!$S$9 -> 1.6969909 | F10: ='05_ALFA'!$F$25*'01_Recursos'!$S$9 -> 0.69073277 | G10: ='05_ALFA'!$G$25*'01_Recursos'!$S$9 -> 6.3625854 | H10: ='05_ALFA'!$H$25*'01_Recursos'!$S$9 -> 1.3112404 | I10: ='05_ALFA'!$I$25*'01_Recursos'!$S$9 -> 10.785993 | J10: ='05_ALFA'!$J$25*'01_Recursos'!$S$9 -> 4.3452908 | K10: ='05_ALFA'!$K$25*'01_Recursos'!$S$9 -> 0.24677845 | L10: ='05_ALFA'!$L$25*'01_Recursos'!$S$9 -> 8.4461835 | M10: ='05_ALFA'!$M$25*'01_Recursos'!$S$9 -> 16.476713 | N10: ='05_ALFA'!$N$25*'01_Recursos'!$S$9 -> 0.11035925 | O10: ='05_ALFA'!$O$25*'01_Recursos'!$S$9 -> 1.1005359 | P10: ='05_ALFA'!$P$25*'01_Recursos'!$S$9 -> 0 | Q10: ='05_ALFA'!$Q$25*'01_Recursos'!$S$9 -> 34.02669 | R10: ='05_ALFA'!$R$25*'01_Recursos'!$S$9 -> 0 | S10: ='05_ALFA'!$S$25*'01_Recursos'!$S$9 -> 4.547372 | T10: ='05_ALFA'!$T$25*'01_Recursos'!$S$9 -> -0.018806148
A11: 09 - Atividades financeiras, de seguros e serviços relacionados | B11: ='05_ALFA'!$B$26*'01_Recursos'!$S$10 -> 0 | C11: ='05_ALFA'!$C$26*'01_Recursos'!$S$10 -> 0 | D11: ='05_ALFA'!$D$26*'01_Recursos'!$S$10 -> 0 | E11: ='05_ALFA'!$E$26*'01_Recursos'!$S$10 -> 0 | F11: ='05_ALFA'!$F$26*'01_Recursos'!$S$10 -> 0 | G11: ='05_ALFA'!$G$26*'01_Recursos'!$S$10 -> 0 | H11: ='05_ALFA'!$H$26*'01_Recursos'!$S$10 -> 0 | I11: ='05_ALFA'!$I$26*'01_Recursos'!$S$10 -> 0 | J11: ='05_ALFA'!$J$26*'01_Recursos'!$S$10 -> 0 | K11: ='05_ALFA'!$K$26*'01_Recursos'!$S$10 -> 0 | L11: ='05_ALFA'!$L$26*'01_Recursos'!$S$10 -> 0 | M11: ='05_ALFA'!$M$26*'01_Recursos'!$S$10 -> 0 | N11: ='05_ALFA'!$N$26*'01_Recursos'!$S$10 -> 0 | O11: ='05_ALFA'!$O$26*'01_Recursos'!$S$10 -> 0 | P11: ='05_ALFA'!$P$26*'01_Recursos'!$S$10 -> 0 | Q11: ='05_ALFA'!$Q$26*'01_Recursos'!$S$10 -> 0 | R11: ='05_ALFA'!$R$26*'01_Recursos'!$S$10 -> 0 | S11: ='05_ALFA'!$S$26*'01_Recursos'!$S$10 -> 0 | T11: ='05_ALFA'!$T$26*'01_Recursos'!$S$10 -> 0
A12: 10 - Atividades imobiliárias | B12: ='05_ALFA'!$B$27*'01_Recursos'!$S$11 -> 0 | C12: ='05_ALFA'!$C$27*'01_Recursos'!$S$11 -> 0 | D12: ='05_ALFA'!$D$27*'01_Recursos'!$S$11 -> 0 | E12: ='05_ALFA'!$E$27*'01_Recursos'!$S$11 -> 0 | F12: ='05_ALFA'!$F$27*'01_Recursos'!$S$11 -> 0 | G12: ='05_ALFA'!$G$27*'01_Recursos'!$S$11 -> 0 | H12: ='05_ALFA'!$H$27*'01_Recursos'!$S$11 -> 0 | I12: ='05_ALFA'!$I$27*'01_Recursos'!$S$11 -> 0 | J12: ='05_ALFA'!$J$27*'01_Recursos'!$S$11 -> 0 | K12: ='05_ALFA'!$K$27*'01_Recursos'!$S$11 -> 0 | L12: ='05_ALFA'!$L$27*'01_Recursos'!$S$11 -> 0 | M12: ='05_ALFA'!$M$27*'01_Recursos'!$S$11 -> 0 | N12: ='05_ALFA'!$N$27*'01_Recursos'!$S$11 -> 0 | O12: ='05_ALFA'!$O$27*'01_Recursos'!$S$11 -> 0 | P12: ='05_ALFA'!$P$27*'01_Recursos'!$S$11 -> 0 | Q12: ='05_ALFA'!$Q$27*'01_Recursos'!$S$11 -> 0 | R12: ='05_ALFA'!$R$27*'01_Recursos'!$S$11 -> 0 | S12: ='05_ALFA'!$S$27*'01_Recursos'!$S$11 -> 0 | T12: ='05_ALFA'!$T$27*'01_Recursos'!$S$11 -> 0
A13: 11 - Outras atividades de serviços | B13: ='05_ALFA'!$B$28*'01_Recursos'!$S$12 -> 0 | C13: ='05_ALFA'!$C$28*'01_Recursos'!$S$12 -> 0 | D13: ='05_ALFA'!$D$28*'01_Recursos'!$S$12 -> 0 | E13: ='05_ALFA'!$E$28*'01_Recursos'!$S$12 -> 0 | F13: ='05_ALFA'!$F$28*'01_Recursos'!$S$12 -> 0 | G13: ='05_ALFA'!$G$28*'01_Recursos'!$S$12 -> 0 | H13: ='05_ALFA'!$H$28*'01_Recursos'!$S$12 -> 0 | I13: ='05_ALFA'!$I$28*'01_Recursos'!$S$12 -> 0 | J13: ='05_ALFA'!$J$28*'01_Recursos'!$S$12 -> 0 | K13: ='05_ALFA'!$K$28*'01_Recursos'!$S$12 -> 0 | L13: ='05_ALFA'!$L$28*'01_Recursos'!$S$12 -> 0 | M13: ='05_ALFA'!$M$28*'01_Recursos'!$S$12 -> 0 | N13: ='05_ALFA'!$N$28*'01_Recursos'!$S$12 -> 0 | O13: ='05_ALFA'!$O$28*'01_Recursos'!$S$12 -> 0 | P13: ='05_ALFA'!$P$28*'01_Recursos'!$S$12 -> 0 | Q13: ='05_ALFA'!$Q$28*'01_Recursos'!$S$12 -> 0 | R13: ='05_ALFA'!$R$28*'01_Recursos'!$S$12 -> 0 | S13: ='05_ALFA'!$S$28*'01_Recursos'!$S$12 -> 0 | T13: ='05_ALFA'!$T$28*'01_Recursos'!$S$12 -> 0
A14: 12 - Administração, defesa, saúde e educação públicas e seguridade social | B14: ='05_ALFA'!$B$29*'01_Recursos'!$S$13 -> 0 | C14: ='05_ALFA'!$C$29*'01_Recursos'!$S$13 -> 0 | D14: ='05_ALFA'!$D$29*'01_Recursos'!$S$13 -> 0 | E14: ='05_ALFA'!$E$29*'01_Recursos'!$S$13 -> 0 | F14: ='05_ALFA'!$F$29*'01_Recursos'!$S$13 -> 0 | G14: ='05_ALFA'!$G$29*'01_Recursos'!$S$13 -> 0 | H14: ='05_ALFA'!$H$29*'01_Recursos'!$S$13 -> 0 | I14: ='05_ALFA'!$I$29*'01_Recursos'!$S$13 -> 0 | J14: ='05_ALFA'!$J$29*'01_Recursos'!$S$13 -> 0 | K14: ='05_ALFA'!$K$29*'01_Recursos'!$S$13 -> 0 | L14: ='05_ALFA'!$L$29*'01_Recursos'!$S$13 -> 0 | M14: ='05_ALFA'!$M$29*'01_Recursos'!$S$13 -> 0 | N14: ='05_ALFA'!$N$29*'01_Recursos'!$S$13 -> 0 | O14: ='05_ALFA'!$O$29*'01_Recursos'!$S$13 -> 0 | P14: ='05_ALFA'!$P$29*'01_Recursos'!$S$13 -> 0 | Q14: ='05_ALFA'!$Q$29*'01_Recursos'!$S$13 -> 0 | R14: ='05_ALFA'!$R$29*'01_Recursos'!$S$13 -> 0 | S14: ='05_ALFA'!$S$29*'01_Recursos'!$S$13 -> 0 | T14: ='05_ALFA'!$T$29*'01_Recursos'!$S$13 -> 0
A16: Margem paga pelos produtos que NAO sao Comercio | B16: =SUM(B3:B14)-B8 -> 530.08976 | C16: =SUM(C3:C14)-C8 -> 13.390523 | D16: =SUM(D3:D14)-D8 -> 930.68362 | E16: =SUM(E3:E14)-E8 -> 95.926995 | F16: =SUM(F3:F14)-F8 -> 446.34406 | G16: =SUM(G3:G14)-G8 -> 210.84388 | H16: =SUM(H3:H14)-H8 -> 167.01554 | I16: =SUM(I3:I14)-I8 -> 24.467931 | ... T16: =SUM(T3:T14)-T8 -> 539.28139
A18: ETAPA 9b - matriz final: a linha de Comercio recebe a compensacao
A19: Produto \ Destino | B19: 01 - Agropecuária | C19: 02 - Indústrias extrativas | D19: 03 - Indústrias de transformação | E19: 04 - Eletricidade e gás, água, esgoto e gestão de resíduos | F19: 05 - Construção | G19: 06 - Comércio | H19: 07 - Transporte, armazenagem e correio | I19: 08 - Informação e comunicação | J19: 09 - Atividades financeiras, de seguros e serviços relacionados | K19: 10 - Atividades imobiliárias | L19: 11 - Outras atividades de serviços | M19: 12 - Administração, defesa, saúde e educação públicas e seguridade social | N19: Exportacoes outros paises | O19: Exportacoes outras UFs | P19: Consumo do governo | Q19: Consumo das familias | R19: Consumo das ISFLSF | S19: FBCF | T19: Variacao de estoques
A20: 01 - Agropecuária | B20: =B$3 -> 29.343952 | C20: =C$3 -> 0.0010203184 | D20: =D$3 -> 138.79214 | E20: =E$3 -> 0.023178998 | F20: =F$3 -> 0.86734532 | G20: =G$3 -> 5.5752916 | H20: =H$3 -> 0 | I20: =I$3 -> 0 | ... T20: =T$3 -> 71.815378
A21: 02 - Indústrias extrativas | B21: =B$4 -> 0.92490211 | C21: =C$4 -> 0.52178504 | D21: =D$4 -> 15.670044 | E21: =E$4 -> 0.42008273 | F21: =F$4 -> 10.631779 | G21: =G$4 -> 0.057067189 | H21: =H$4 -> 0.00048089466 | I21: =I$4 -> 0 | ... T21: =T$4 -> 6.3070835
A22: 03 - Indústrias de transformação | B22: =B$5 -> 499.37195 | C22: =C$5 -> 12.836672 | D22: =D$5 -> 773.83462 | E22: =E$5 -> 89.737138 | F22: =F$5 -> 434.12408 | G22: =G$5 -> 198.14976 | H22: =H$5 -> 165.63239 | I22: =I$5 -> 13.622463 | ... T22: =T$5 -> 461.17316
A23: 04 - Eletricidade e gás, água, esgoto e gestão de resíduos | B23: =B$6 -> 0.42350351 | C23: =C$6 -> 0.021614082 | D23: =D$6 -> 0.37469015 | E23: =E$6 -> 4.0496039 | F23: =F$6 -> 0.030118319 | G23: =G$6 -> 0.69917866 | H23: =H$6 -> 0.071431661 | I23: =I$6 -> 0.059475171 | ... T23: =T$6 -> 0.0045729375
A24: 05 - Construção | B24: =B$7 -> 0 | C24: =C$7 -> 0 | D24: =D$7 -> 0 | E24: =E$7 -> 0 | F24: =F$7 -> 0 | G24: =G$7 -> 0 | H24: =H$7 -> 0 | I24: =I$7 -> 0 | ... T24: =T$7 -> 0
A25: 06 - Comércio | B25: =-B$16 -> -530.08976 | C25: =-C$16 -> -13.390523 | D25: =-D$16 -> -930.68362 | E25: =-E$16 -> -95.926995 | F25: =-F$16 -> -446.34406 | G25: =-G$16 -> -210.84388 | H25: =-H$16 -> -167.01554 | I25: =-I$16 -> -24.467931 | ... T25: =-T$16 -> -539.28139
A26: 07 - Transporte, armazenagem e correio | B26: =B$9 -> 0 | C26: =C$9 -> 0 | D26: =D$9 -> 0 | E26: =E$9 -> 0 | F26: =F$9 -> 0 | G26: =G$9 -> 0 | H26: =H$9 -> 0 | I26: =I$9 -> 0 | ... T26: =T$9 -> 0
A27: 08 - Informação e comunicação | B27: =B$10 -> 0.02545683 | C27: =C$10 -> 0.0094321776 | D27: =D$10 -> 2.012119 | E27: =E$10 -> 1.6969909 | F27: =F$10 -> 0.69073277 | G27: =G$10 -> 6.3625854 | H27: =H$10 -> 1.3112404 | I27: =I$10 -> 10.785993 | ... T27: =T$10 -> -0.018806148
A28: 09 - Atividades financeiras, de seguros e serviços relacionados | B28: =B$11 -> 0 | C28: =C$11 -> 0 | D28: =D$11 -> 0 | E28: =E$11 -> 0 | F28: =F$11 -> 0 | G28: =G$11 -> 0 | H28: =H$11 -> 0 | I28: =I$11 -> 0 | ... T28: =T$11 -> 0
A29: 10 - Atividades imobiliárias | B29: =B$12 -> 0 | C29: =C$12 -> 0 | D29: =D$12 -> 0 | E29: =E$12 -> 0 | F29: =F$12 -> 0 | G29: =G$12 -> 0 | H29: =H$12 -> 0 | I29: =I$12 -> 0 | ... T29: =T$12 -> 0
A30: 11 - Outras atividades de serviços | B30: =B$13 -> 0 | C30: =C$13 -> 0 | D30: =D$13 -> 0 | E30: =E$13 -> 0 | F30: =F$13 -> 0 | G30: =G$13 -> 0 | H30: =H$13 -> 0 | I30: =I$13 -> 0 | ... T30: =T$13 -> 0
A31: 12 - Administração, defesa, saúde e educação públicas e seguridade social | B31: =B$14 -> 0 | C31: =C$14 -> 0 | D31: =D$14 -> 0 | E31: =E$14 -> 0 | F31: =F$14 -> 0 | G31: =G$14 -> 0 | H31: =H$14 -> 0 | I31: =I$14 -> 0 | ... T31: =T$14 -> 0
A33: Conferencia: soma da coluna (deve ser 0) | B33: =SUM(B20:B31) -> 1.7329888e-14 | C33: =SUM(C20:C31) -> -1.179612e-16 | D33: =SUM(D20:D31) -> -2.8421709e-14 | E33: =SUM(E20:E31) -> -4.6629367e-15 | F33: =SUM(F20:F31) -> -2.2315483e-14 | G33: =SUM(G20:G31) -> -6.2172489e-15 | H33: =SUM(H20:H31) -> -2.6867397e-14 | I33: =SUM(I20:I31) -> -5.3290705e-15 | ... T33: =SUM(T20:T31) -> -2.4577562e-14

Sheet 07_M_transporte
A1: ETAPA 10a - margem de Transporte embutida em cada celula (ALFA x margem do produto)
A2: Produto \ Destino | B2: 01 - Agropecuária | C2: 02 - Indústrias extrativas | D2: 03 - Indústrias de transformação | E2: 04 - Eletricidade e gás, água, esgoto e gestão de resíduos | F2: 05 - Construção | G2: 06 - Comércio | H2: 07 - Transporte, armazenagem e correio | I2: 08 - Informação e comunicação | J2: 09 - Atividades financeiras, de seguros e serviços relacionados | K2: 10 - Atividades imobiliárias | L2: 11 - Outras atividades de serviços | M2: 12 - Administração, defesa, saúde e educação públicas e seguridade social | N2: Exportacoes outros paises | O2: Exportacoes outras UFs | P2: Consumo do governo | Q2: Consumo das familias | R2: Consumo das ISFLSF | S2: FBCF | T2: Variacao de estoques
A3: 01 - Agropecuária | B3: ='05_ALFA'!$B$18*'01_Recursos'!$T$2 -> 4.1062249 | C3: ='05_ALFA'!$C$18*'01_Recursos'!$T$2 -> 0.00014277752 | D3: ='05_ALFA'!$D$18*'01_Recursos'!$T$2 -> 19.421779 | E3: ='05_ALFA'!$E$18*'01_Recursos'!$T$2 -> 0.0032435365 | F3: ='05_ALFA'!$F$18*'01_Recursos'!$T$2 -> 0.12137135 | G3: ='05_ALFA'!$G$18*'01_Recursos'!$T$2 -> 0.78017444 | H3: ='05_ALFA'!$H$18*'01_Recursos'!$T$2 -> 0 | I3: ='05_ALFA'!$I$18*'01_Recursos'!$T$2 -> 0 | J3: ='05_ALFA'!$J$18*'01_Recursos'!$T$2 -> 0 | K3: ='05_ALFA'!$K$18*'01_Recursos'!$T$2 -> 0 | L3: ='05_ALFA'!$L$18*'01_Recursos'!$T$2 -> 0.82850905 | M3: ='05_ALFA'!$M$18*'01_Recursos'!$T$2 -> 0.55123479 | N3: ='05_ALFA'!$N$18*'01_Recursos'!$T$2 -> 25.303664 | O3: ='05_ALFA'!$O$18*'01_Recursos'!$T$2 -> 15.49155 | P3: ='05_ALFA'!$P$18*'01_Recursos'!$T$2 -> 0.014876217 | Q3: ='05_ALFA'!$Q$18*'01_Recursos'!$T$2 -> 36.282567 | R3: ='05_ALFA'!$R$18*'01_Recursos'!$T$2 -> 0 | S3: ='05_ALFA'!$S$18*'01_Recursos'!$T$2 -> 2.0452289 | T3: ='05_ALFA'!$T$18*'01_Recursos'!$T$2 -> 10.049434
A4: 02 - Indústrias extrativas | B4: ='05_ALFA'!$B$19*'01_Recursos'!$T$3 -> 1.0899909 | C4: ='05_ALFA'!$C$19*'01_Recursos'!$T$3 -> 0.61492013 | D4: ='05_ALFA'!$D$19*'01_Recursos'!$T$3 -> 18.46704 | E4: ='05_ALFA'!$E$19*'01_Recursos'!$T$3 -> 0.49506464 | F4: ='05_ALFA'!$F$19*'01_Recursos'!$T$3 -> 12.52948 | G4: ='05_ALFA'!$G$19*'01_Recursos'!$T$3 -> 0.067253295 | H4: ='05_ALFA'!$H$19*'01_Recursos'!$T$3 -> 0.0005667311 | I4: ='05_ALFA'!$I$19*'01_Recursos'!$T$3 -> 0 | J4: ='05_ALFA'!$J$19*'01_Recursos'!$T$3 -> 0 | K4: ='05_ALFA'!$K$19*'01_Recursos'!$T$3 -> 0.72879253 | L4: ='05_ALFA'!$L$19*'01_Recursos'!$T$3 -> 0.050501344 | M4: ='05_ALFA'!$M$19*'01_Recursos'!$T$3 -> 0.24902722 | N4: ='05_ALFA'!$N$19*'01_Recursos'!$T$3 -> 0.44817446 | O4: ='05_ALFA'!$O$19*'01_Recursos'!$T$3 -> 10.826333 | P4: ='05_ALFA'!$P$19*'01_Recursos'!$T$3 -> 0 | Q4: ='05_ALFA'!$Q$19*'01_Recursos'!$T$3 -> 0 | R4: ='05_ALFA'!$R$19*'01_Recursos'!$T$3 -> 0 | S4: ='05_ALFA'!$S$19*'01_Recursos'!$T$3 -> 0 | T4: ='05_ALFA'!$T$19*'01_Recursos'!$T$3 -> 7.4328551
A5: 03 - Indústrias de transformação | B5: ='05_ALFA'!$B$20*'01_Recursos'!$T$4 -> 20.790808 | C5: ='05_ALFA'!$C$20*'01_Recursos'!$T$4 -> 0.53444087 | D5: ='05_ALFA'!$D$20*'01_Recursos'!$T$4 -> 32.217763 | E5: ='05_ALFA'!$E$20*'01_Recursos'!$T$4 -> 3.7361082 | F5: ='05_ALFA'!$F$20*'01_Recursos'!$T$4 -> 18.074284 | G5: ='05_ALFA'!$G$20*'01_Recursos'!$T$4 -> 8.2497499 | H5: ='05_ALFA'!$H$20*'01_Recursos'!$T$4 -> 6.8959244 | I5: ='05_ALFA'!$I$20*'01_Recursos'!$T$4 -> 0.56715642 | J5: ='05_ALFA'!$J$20*'01_Recursos'!$T$4 -> 0.28564397 | K5: ='05_ALFA'!$K$20*'01_Recursos'!$T$4 -> 0.4769545 | L5: ='05_ALFA'!$L$20*'01_Recursos'!$T$4 -> 10.891171 | M5: ='05_ALFA'!$M$20*'01_Recursos'!$T$4 -> 8.6887421 | N5: ='05_ALFA'!$N$20*'01_Recursos'!$T$4 -> 4.7772486 | O5: ='05_ALFA'!$O$20*'01_Recursos'!$T$4 -> 45.192052 | P5: ='05_ALFA'!$P$20*'01_Recursos'!$T$4 -> 1.0027478 | Q5: ='05_ALFA'!$Q$20*'01_Recursos'!$T$4 -> 206.70559 | R5: ='05_ALFA'!$R$20*'01_Recursos'!$T$4 -> 0 | S5: ='05_ALFA'!$S$20*'01_Recursos'!$T$4 -> 20.713172 | T5: ='05_ALFA'!$T$20*'01_Recursos'!$T$4 -> 19.200443
A6: 04 - Eletricidade e gás, água, esgoto e gestão de resíduos | B6: ='05_ALFA'!$B$21*'01_Recursos'!$T$5 -> 0 | C6: ='05_ALFA'!$C$21*'01_Recursos'!$T$5 -> 0 | D6: ='05_ALFA'!$D$21*'01_Recursos'!$T$5 -> 0 | E6: ='05_ALFA'!$E$21*'01_Recursos'!$T$5 -> 0 | F6: ='05_ALFA'!$F$21*'01_Recursos'!$T$5 -> 0 | G6: ='05_ALFA'!$G$21*'01_Recursos'!$T$5 -> 0 | H6: ='05_ALFA'!$H$21*'01_Recursos'!$T$5 -> 0 | I6: ='05_ALFA'!$I$21*'01_Recursos'!$T$5 -> 0 | J6: ='05_ALFA'!$J$21*'01_Recursos'!$T$5 -> 0 | K6: ='05_ALFA'!$K$21*'01_Recursos'!$T$5 -> 0 | L6: ='05_ALFA'!$L$21*'01_Recursos'!$T$5 -> 0 | M6: ='05_ALFA'!$M$21*'01_Recursos'!$T$5 -> 0 | N6: ='05_ALFA'!$N$21*'01_Recursos'!$T$5 -> 0 | O6: ='05_ALFA'!$O$21*'01_Recursos'!$T$5 -> 0 | P6: ='05_ALFA'!$P$21*'01_Recursos'!$T$5 -> 0 | Q6: ='05_ALFA'!$Q$21*'01_Recursos'!$T$5 -> 0 | R6: ='05_ALFA'!$R$21*'01_Recursos'!$T$5 -> 0 | S6: ='05_ALFA'!$S$21*'01_Recursos'!$T$5 -> 0 | T6: ='05_ALFA'!$T$21*'01_Recursos'!$T$5 -> 0
A7: 05 - Construção | B7: ='05_ALFA'!$B$22*'01_Recursos'!$T$6 -> 0 | C7: ='05_ALFA'!$C$22*'01_Recursos'!$T$6 -> 0 | D7: ='05_ALFA'!$D$22*'01_Recursos'!$T$6 -> 0 | E7: ='05_ALFA'!$E$22*'01_Recursos'!$T$6 -> 0 | F7: ='05_ALFA'!$F$22*'01_Recursos'!$T$6 -> 0 | G7: ='05_ALFA'!$G$22*'01_Recursos'!$T$6 -> 0 | H7: ='05_ALFA'!$H$22*'01_Recursos'!$T$6 -> 0 | I7: ='05_ALFA'!$I$22*'01_Recursos'!$T$6 -> 0 | J7: ='05_ALFA'!$J$22*'01_Recursos'!$T$6 -> 0 | K7: ='05_ALFA'!$K$22*'01_Recursos'!$T$6 -> 0 | L7: ='05_ALFA'!$L$22*'01_Recursos'!$T$6 -> 0 | M7: ='05_ALFA'!$M$22*'01_Recursos'!$T$6 -> 0 | N7: ='05_ALFA'!$N$22*'01_Recursos'!$T$6 -> 0 | O7: ='05_ALFA'!$O$22*'01_Recursos'!$T$6 -> 0 | P7: ='05_ALFA'!$P$22*'01_Recursos'!$T$6 -> 0 | Q7: ='05_ALFA'!$Q$22*'01_Recursos'!$T$6 -> 0 | R7: ='05_ALFA'!$R$22*'01_Recursos'!$T$6 -> 0 | S7: ='05_ALFA'!$S$22*'01_Recursos'!$T$6 -> 0 | T7: ='05_ALFA'!$T$22*'01_Recursos'!$T$6 -> 0
A8: 06 - Comércio | B8: ='05_ALFA'!$B$23*'01_Recursos'!$T$7 -> 0 | C8: ='05_ALFA'!$C$23*'01_Recursos'!$T$7 -> 0 | D8: ='05_ALFA'!$D$23*'01_Recursos'!$T$7 -> 0 | E8: ='05_ALFA'!$E$23*'01_Recursos'!$T$7 -> 0 | F8: ='05_ALFA'!$F$23*'01_Recursos'!$T$7 -> 0 | G8: ='05_ALFA'!$G$23*'01_Recursos'!$T$7 -> 0 | H8: ='05_ALFA'!$H$23*'01_Recursos'!$T$7 -> 0 | I8: ='05_ALFA'!$I$23*'01_Recursos'!$T$7 -> 0 | J8: ='05_ALFA'!$J$23*'01_Recursos'!$T$7 -> 0 | K8: ='05_ALFA'!$K$23*'01_Recursos'!$T$7 -> 0 | L8: ='05_ALFA'!$L$23*'01_Recursos'!$T$7 -> 0 | M8: ='05_ALFA'!$M$23*'01_Recursos'!$T$7 -> 0 | N8: ='05_ALFA'!$N$23*'01_Recursos'!$T$7 -> 0 | O8: ='05_ALFA'!$O$23*'01_Recursos'!$T$7 -> 0 | P8: ='05_ALFA'!$P$23*'01_Recursos'!$T$7 -> 0 | Q8: ='05_ALFA'!$Q$23*'01_Recursos'!$T$7 -> 0 | R8: ='05_ALFA'!$R$23*'01_Recursos'!$T$7 -> 0 | S8: ='05_ALFA'!$S$23*'01_Recursos'!$T$7 -> 0 | T8: ='05_ALFA'!$T$23*'01_Recursos'!$T$7 -> 0
A9: 07 - Transporte, armazenagem e correio | B9: ='05_ALFA'!$B$24*'01_Recursos'!$T$8 -> -22.051811 | C9: ='05_ALFA'!$C$24*'01_Recursos'!$T$8 -> -1.2257524 | D9: ='05_ALFA'!$D$24*'01_Recursos'!$T$8 -> -79.703333 | E9: ='05_ALFA'!$E$24*'01_Recursos'!$T$8 -> -4.4183008 | F9: ='05_ALFA'!$F$24*'01_Recursos'!$T$8 -> -6.8851318 | G9: ='05_ALFA'!$G$24*'01_Recursos'!$T$8 -> -93.525878 | H9: ='05_ALFA'!$H$24*'01_Recursos'!$T$8 -> -59.963369 | I9: ='05_ALFA'!$I$24*'01_Recursos'!$T$8 -> -2.1630987 | J9: ='05_ALFA'!$J$24*'01_Recursos'!$T$8 -> -5.4996367 | K9: ='05_ALFA'!$K$24*'01_Recursos'!$T$8 -> -0.37277871 | L9: ='05_ALFA'!$L$24*'01_Recursos'!$T$8 -> -26.178179 | M9: ='05_ALFA'!$M$24*'01_Recursos'!$T$8 -> -40.31223 | N9: ='05_ALFA'!$N$24*'01_Recursos'!$T$8 -> -3.1462782 | O9: ='05_ALFA'!$O$24*'01_Recursos'!$T$8 -> 0 | P9: ='05_ALFA'!$P$24*'01_Recursos'!$T$8 -> 0 | Q9: ='05_ALFA'!$Q$24*'01_Recursos'!$T$8 -> -231.55422 | R9: ='05_ALFA'!$R$24*'01_Recursos'!$T$8 -> 0 | S9: ='05_ALFA'!$S$24*'01_Recursos'!$T$8 -> 0 | T9: ='05_ALFA'!$T$24*'01_Recursos'!$T$8 -> 0
